<?xml version="1.0" encoding="utf-8"?>
<!-- This URDF was automatically created by SolidWorks to URDF Exporter! Originally created by Stephen Brawner (brawner@gmail.com) 
     Commit Version: 1.6.0-1-g15f4949  Build Version: 1.6.7594.29634
     For more information, please see http://wiki.ros.org/sw_urdf_exporter -->
<robot
  name="EnsamblajeRobot.SLDASM">
  <link
    name="base_link">
    <inertial>
      <origin
        xyz="0.0084898 9.442E-05 0.02429"
        rpy="0 0 0" />
      <mass
        value="0.13875" />
      <inertia
        ixx="4.9874E-05"
        ixy="-1.4398E-08"
        ixz="-3.1771E-07"
        iyy="6.394E-05"
        iyz="-4.4077E-09"
        izz="5.7156E-05" />
    </inertial>
    <visual>
      <origin
        xyz="0 0 0"
        rpy="0 0 0" />
      <geometry>
        <mesh
          filename="package://EnsamblajeRobot.SLDASM/meshes/base_link.STL" />
      </geometry>
      <material
        name="">
        <color
          rgba="0.75294 0.75294 0.75294 1" />
      </material>
    </visual>
    <collision>
      <origin
        xyz="0 0 0"
        rpy="0 0 0" />
      <geometry>
        <mesh
          filename="package://EnsamblajeRobot.SLDASM/meshes/base_link.STL" />
      </geometry>
    </collision>
  </link>
  <link
    name="waist_link">
    <inertial>
      <origin
        xyz="0.039723 -0.0019578 0.034617"
        rpy="0 0 0" />
      <mass
        value="0.13759" />
      <inertia
        ixx="4.4295E-05"
        ixy="-3.4932E-07"
        ixz="8.0728E-06"
        iyy="5.0403E-05"
        iyz="4.3166E-08"
        izz="4.172E-05" />
    </inertial>
    <visual>
      <origin
        xyz="0 0 0"
        rpy="0 0 0" />
      <geometry>
        <mesh
          filename="package://EnsamblajeRobot.SLDASM/meshes/waist_link.STL" />
      </geometry>
      <material
        name="">
        <color
          rgba="48 50 49 1" />
      </material>
    </visual>
    <collision>
      <origin
        xyz="0 0 0"
        rpy="0 0 0" />
      <geometry>
        <mesh
          filename="package://EnsamblajeRobot.SLDASM/meshes/waist_link.STL" />
      </geometry>
    </collision>
  </link>
  <joint
    name="base_waist_joint"
    type="revolute">
    <origin
      xyz="0.041313 7.9909E-05 0.006"
      rpy="0 0 0" />
    <parent
      link="base_link" />
    <child
      link="waist_link" />
    <axis
      xyz="0 0 1" />
    <limit
      lower="-1.0472"
      upper="1.0472"
      effort="1.765"
      velocity="10.157" />
  </joint>
  <link
    name="shoulder_link">
    <inertial>
      <origin
        xyz="2.1317E-05 0.036161 0.048291"
        rpy="0 0 0" />
      <mass
        value="0.063318" />
      <inertia
        ixx="1.808E-05"
        ixy="-1.4249E-09"
        ixz="1.0432E-08"
        iyy="1.2539E-05"
        iyz="1.858E-07"
        izz="1.2788E-05" />
    </inertial>
    <visual>
      <origin
        xyz="0 0 0"
        rpy="0 0 0" />
      <geometry>
        <mesh
          filename="package://EnsamblajeRobot.SLDASM/meshes/shoulder_link.STL" />
      </geometry>
      <material
        name="">
        <color
          rgba="31 78 121 1" />
      </material>
    </visual>
    <collision>
      <origin
        xyz="0 0 0"
        rpy="0 0 0" />
      <geometry>
        <mesh
          filename="package://EnsamblajeRobot.SLDASM/meshes/shoulder_link.STL" />
      </geometry>
    </collision>
  </link>
  <joint
    name="waist_shoulder_joint"
    type="revolute">
    <origin
      xyz="0.045 -0.00425 0.047979"
      rpy="0 0 0" />
    <parent
      link="waist_link" />
    <child
      link="shoulder_link" />
    <axis
      xyz="0 1 0" />
    <limit
      lower="-1.0472"
      upper="1.0472"
      effort="1.765"
      velocity="10.157" />
  </joint>
  <link
    name="arm_link">
    <inertial>
      <origin
        xyz="-2.1317E-05 -0.036161 0.045745"
        rpy="0 0 0" />
      <mass
        value="0.063318" />
      <inertia
        ixx="1.808E-05"
        ixy="-1.4249E-09"
        ixz="-1.0432E-08"
        iyy="1.2539E-05"
        iyz="-1.858E-07"
        izz="1.2788E-05" />
    </inertial>
    <visual>
      <origin
        xyz="0 0 0"
        rpy="0 0 0" />
      <geometry>
        <mesh
          filename="package://EnsamblajeRobot.SLDASM/meshes/arm_link.STL" />
      </geometry>
      <material
        name="">
        <color
          rgba="48 157 181 1" />
      </material>
    </visual>
    <collision>
      <origin
        xyz="0 0 0"
        rpy="0 0 0" />
      <geometry>
        <mesh
          filename="package://EnsamblajeRobot.SLDASM/meshes/arm_link.STL" />
      </geometry>
    </collision>
  </link>
  <joint
    name="shoulder_arm_joint"
    type="revolute">
    <origin
      xyz="0 0.0445 0.074046"
      rpy="0 0 0" />
    <parent
      link="shoulder_link" />
    <child
      link="arm_link" />
    <axis
      xyz="0 1 0" />
    <limit
      lower="-1.0472"
      upper="1.0472"
      effort="1.765"
      velocity="10.157" />
  </joint>
  <link
    name="wrist_link">
    <inertial>
      <origin
        xyz="0.013261 -2.0895E-05 0.06379"
        rpy="0 0 0" />
      <mass
        value="0.063767" />
      <inertia
        ixx="1.663E-05"
        ixy="1.052E-08"
        ixz="-2.7618E-07"
        iyy="1.8523E-05"
        iyz="1.4564E-09"
        izz="1.851E-05" />
    </inertial>
    <visual>
      <origin
        xyz="0 0 0"
        rpy="0 0 0" />
      <geometry>
        <mesh
          filename="package://EnsamblajeRobot.SLDASM/meshes/wrist_link.STL" />
      </geometry>
      <material
        name="">
        <color
          rgba="1 1 1 1" />
      </material>
    </visual>
    <collision>
      <origin
        xyz="0 0 0"
        rpy="0 0 0" />
      <geometry>
        <mesh
          filename="package://EnsamblajeRobot.SLDASM/meshes/wrist_link.STL" />
      </geometry>
    </collision>
  </link>
  <joint
    name="arm_wrist_joint"
    type="revolute">
    <origin
      xyz="0 -0.044 0.068954"
      rpy="0 0 0" />
    <parent
      link="arm_link" />
    <child
      link="wrist_link" />
    <axis
      xyz="0 1 0" />
    <limit
      lower="-1.0472"
      upper="1.0472"
      effort="1.765"
      velocity="10.157" />
  </joint>
  <link
    name="end_efector">
    <inertial>
      <origin
        xyz="0.00073639 -4.8026E-15 -0.033697"
        rpy="0 0 0" />
      <mass
        value="0.014877" />
      <inertia
        ixx="4.3491E-06"
        ixy="-3.2048E-21"
        ixz="1.166E-08"
        iyy="3.2694E-06"
        iyz="-8.8224E-20"
        izz="6.1015E-06" />
    </inertial>
    <visual>
      <origin
        xyz="0 0 0"
        rpy="0 0 0" />
      <geometry>
        <mesh
          filename="package://EnsamblajeRobot.SLDASM/meshes/end_efector.STL" />
      </geometry>
      <material
        name="">
        <color
          rgba="1 1 1 1" />
      </material>
    </visual>
    <collision>
      <origin
        xyz="0 0 0"
        rpy="0 0 0" />
      <geometry>
        <mesh
          filename="package://EnsamblajeRobot.SLDASM/meshes/end_efector.STL" />
      </geometry>
    </collision>
  </link>
  <joint
    name="EF"
    type="fixed">
    <origin
      xyz="0.0055201 0 0.132"
      rpy="0 0 0" />
    <parent
      link="wrist_link" />
    <child
      link="end_efector" />
    <axis
      xyz="0 0 0" />
  </joint>
</robot>